Workbook
Name table1: 'Engine Deck'!#REF!

Sheet A320 Wing
A1: Wing Planform
A2: Span (m) | B2: Area (m^2) | C2: Root Chord (m) | D2: Tip Chord (m)
A3: 34.32 | B3: 124.02 | C3: 6.18 | D3: 1.05
A4: Mean Chord (m) | B4: AR | C4: Average 1/4 Chord Sweep (rad)
A5: 4.32 | B5: =A3^2/B3 -> 9.4973585 | C5: =25*PI()/180 -> 0.43633231
A7: Sections
A8: Section Number | B8: 0 (Fuselage) | C8: 1 (Root) | D8: 2 (Kink) | E8: 3 (Tip)
A9: Chord (m) | B9: 6.1810481 | C9: 6.1810481 | D9: 4.4345343 | E9: 1.0507782
A10: Spanwise Location (m) | B10: 0 | C10: 1.9839934 | D10: 5.1487331 | E10: 17.162444
A11: LE Sweep (rad) | B11: - | C11: =31.14*PI()/180 -> 0.54349553 | D11: =28.22*PI()/180 -> 0.49253191 | E11: =28.22*PI()/180 -> 0.49253191
A12: t/c | B12: 0.15 | C12: 0.15 | D12: 0.1368 | E12: 0.0865
A14: Wing Location
A15: x (m) | B15: y (m) | C15: z (m)
A16: 12.423654 | B16: 0 | C16: -1.2330717
A17: CoG x (m) | B17: CoG y (m) | C17: CoG z (m)
A18: 16.39 | B18: 0 | C18: -0.92
A19: Aerodynamic Center x(m)
A20: 15.6 | C20: 15.6
A21: Incidence Angle (rad)
A22: =1*PI()/180 -> 0.017453293
A24: Lift Curve Slope (1/rad) | B24: Mach | C24: Airfoil/Pressure Influence
A25: =2*PI()*$B$5/(2+SQRT(4+$B$5^2*(1-B25^2)/$C$25*(1+TAN($C$5)^2/(1-B25^2)))) -> 5.1116967 | B25: 0.1 | C25: =(1+0.75*D12)^2 -> 1.2157268
A26: =2*PI()*$B$5/(2+SQRT(4+$B$5^2*(1-B26^2)/$C$25*(1+TAN($C$5)^2/(1-B26^2)))) -> 5.1328251 | B26: 0.15
A27: =2*PI()*$B$5/(2+SQRT(4+$B$5^2*(1-B27^2)/$C$25*(1+TAN($C$5)^2/(1-B27^2)))) -> 5.1628811 | B27: 0.2
A28: =2*PI()*$B$5/(2+SQRT(4+$B$5^2*(1-B28^2)/$C$25*(1+TAN($C$5)^2/(1-B28^2)))) -> 5.2023681 | B28: 0.25
A29: =2*PI()*$B$5/(2+SQRT(4+$B$5^2*(1-B29^2)/$C$25*(1+TAN($C$5)^2/(1-B29^2)))) -> 5.2519739 | B29: 0.3
A30: =2*PI()*$B$5/(2+SQRT(4+$B$5^2*(1-B30^2)/$C$25*(1+TAN($C$5)^2/(1-B30^2)))) -> 5.3126076 | B30: 0.35
A31: =2*PI()*$B$5/(2+SQRT(4+$B$5^2*(1-B31^2)/$C$25*(1+TAN($C$5)^2/(1-B31^2)))) -> 5.3854507 | B31: 0.4
A32: =2*PI()*$B$5/(2+SQRT(4+$B$5^2*(1-B32^2)/$C$25*(1+TAN($C$5)^2/(1-B32^2)))) -> 5.4356353 | B32: 0.43
A33: =2*PI()*$B$5/(2+SQRT(4+$B$5^2*(1-B33^2)/$C$25*(1+TAN($C$5)^2/(1-B33^2)))) -> 5.4720308 | B33: 0.45
A34: =2*PI()*$B$5/(2+SQRT(4+$B$5^2*(1-B34^2)/$C$25*(1+TAN($C$5)^2/(1-B34^2)))) -> 5.5743259 | B34: 0.5
A35: =2*PI()*$B$5/(2+SQRT(4+$B$5^2*(1-B35^2)/$C$25*(1+TAN($C$5)^2/(1-B35^2)))) -> 5.6949167 | B35: 0.55
A36: =2*PI()*$B$5/(2+SQRT(4+$B$5^2*(1-B36^2)/$C$25*(1+TAN($C$5)^2/(1-B36^2)))) -> 5.8372136 | B36: 0.6
A37: =2*PI()*$B$5/(2+SQRT(4+$B$5^2*(1-B37^2)/$C$25*(1+TAN($C$5)^2/(1-B37^2)))) -> 6.0058029 | B37: 0.65
... A41: =2*PI()*$B$5/(2+SQRT(4+$B$5^2*(1-B41^2)/$C$25*(1+TAN($C$5)^2/(1-B41^2)))) -> 6.6205687 | B41: 0.78
A43: Cm0 | B43: CM0 | C43: CL0
A44: -0.04 | B44: =A44*(B5*COS(C5)^2)/(B5+2*COS(C5)) -> -0.027590059 | C44: 0.12
A46: Dry Wing Mass (kg)
A47: 8227.3
A49: CD0 | B49: k
...

Sheet Engine Deck
A1: Mach | B1: a | D1: Altitude | E1: Temp | F1: Pressure | G1: Density | I1: T_SL
A2: 0 | B2: 340.3 | D2: 0 | E2: 288.15 | F2: 10.13 | G2: 1.225 | I2: 105000
A3: 0.1 | B3: 336.4 | D3: 1000 | E3: 281.7 | F3: 8.988 | G3: 1.112
A4: 0.2 | B4: 332.5 | D4: 2000 | E4: 275.2 | F4: 7.95 | G4: 1.007
A5: 0.3 | B5: 328.6 | D5: 3000 | E5: 268.7 | F5: 7.012 | G5: 0.9093
A6: 0.4 | B6: 324.6 | D6: 4000 | E6: 262.2 | F6: 6.166 | G6: 0.8194
A7: 0.5 | B7: 320.5 | D7: 5000 | E7: 255.7 | F7: 5.405 | G7: 0.7364 | S7: 0 | T7: 15 | U7: 9.807 | V7: 10.13 | W7: 1.225 | X7: 1.789
A8: 0.6 | B8: 316.5 | D8: 6000 | E8: 249.2 | F8: 4.722 | G8: 0.6601 | S8: 1000 | T8: 8.5 | U8: 9.804 | V8: 8.988 | W8: 1.112 | X8: 1.758
A9: 0.7 | B9: 312.3 | D9: 7000 | E9: 242.7 | F9: 4.111 | G9: 0.59 | S9: 2000 | T9: 2 | U9: 9.801 | V9: 7.95 | W9: 1.007 | X9: 1.726
A10: 0.8 | B10: 308.1 | D10: 8000 | E10: 236.2 | F10: 3.565 | G10: 0.5258 | S10: 3000 | T10: -4.49 | U10: 9.797 | V10: 7.012 | W10: 0.9093 | X10: 1.694
A11: 0.9 | B11: 303.8 | D11: 9000 | E11: 229.7 | F11: 3.08 | G11: 0.4671 | S11: 4000 | T11: -10.98 | U11: 9.794 | V11: 6.166 | W11: 0.8194 | X11: 1.661
A12: 1 | B12: 299.5 | D12: 10000 | E12: 223.3 | F12: 2.65 | G12: 0.4135 | S12: 5000 | T12: -17.47 | U12: 9.791 | V12: 5.405 | W12: 0.7364 | X12: 1.628
S13: 6000 | T13: -23.96 | U13: 9.788 | V13: 4.722 | W13: 0.6601 | X13: 1.595
S14: 7000 | T14: -30.45 | U14: 9.785 | V14: 4.111 | W14: 0.59 | X14: 1.561
S15: 8000 | T15: -36.94 | U15: 9.782 | V15: 3.565 | W15: 0.5258 | X15: 1.527
S16: 9000 | T16: -43.42 | U16: 9.779 | V16: 3.08 | W16: 0.4671 | X16: 1.493
S17: 10000 | T17: -49.9 | U17: 9.776 | V17: 2.65 | W17: 0.4135 | X17: 1.458
A19: theta0 | B19: Mach
B20: 0 | C20: 0.1 | D20: 0.2 | E20: 0.3 | F20: 0.4 | G20: 0.5 | H20: 0.6 | I20: 0.7 | J20: 0.8 | K20: 0.9 | L20: 1
A21: 0 | B21: =$E2/$E$2*(1+0.4/2*B$20^2) -> 1 | C21: =$E2/$E$2*(1+0.4/2*C$20^2) -> 1.002 | D21: =$E2/$E$2*(1+0.4/2*D$20^2) -> 1.008 | E21: =$E2/$E$2*(1+0.4/2*E$20^2) -> 1.018 | F21: =$E2/$E$2*(1+0.4/2*F$20^2) -> 1.032 | G21: =$E2/$E$2*(1+0.4/2*G$20^2) -> 1.05 | H21: =$E2/$E$2*(1+0.4/2*H$20^2) -> 1.072 | I21: =$E2/$E$2*(1+0.4/2*I$20^2) -> 1.098 | ... L21: =$E2/$E$2*(1+0.4/2*L$20^2) -> 1.2 | M21: Altitude
A22: 1000 | B22: =$E3/$E$2*(1+0.4/2*B$20^2) -> 0.97761583 | C22: =$E3/$E$2*(1+0.4/2*C$20^2) -> 0.97957106 | D22: =$E3/$E$2*(1+0.4/2*D$20^2) -> 0.98543675 | E22: =$E3/$E$2*(1+0.4/2*E$20^2) -> 0.99521291 | F22: =$E3/$E$2*(1+0.4/2*F$20^2) -> 1.0088995 | G22: =$E3/$E$2*(1+0.4/2*G$20^2) -> 1.0264966 | H22: =$E3/$E$2*(1+0.4/2*H$20^2) -> 1.0480042 | I22: =$E3/$E$2*(1+0.4/2*I$20^2) -> 1.0734222 | ... L22: =$E3/$E$2*(1+0.4/2*L$20^2) -> 1.173139
A23: 2000 | B23: =$E4/$E$2*(1+0.4/2*B$20^2) -> 0.95505813 | C23: =$E4/$E$2*(1+0.4/2*C$20^2) -> 0.95696825 | D23: =$E4/$E$2*(1+0.4/2*D$20^2) -> 0.96269859 | E23: =$E4/$E$2*(1+0.4/2*E$20^2) -> 0.97224918 | F23: =$E4/$E$2*(1+0.4/2*F$20^2) -> 0.98561999 | G23: =$E4/$E$2*(1+0.4/2*G$20^2) -> 1.002811 | H23: =$E4/$E$2*(1+0.4/2*H$20^2) -> 1.0238223 | I23: =$E4/$E$2*(1+0.4/2*I$20^2) -> 1.0486538 | ... L23: =$E4/$E$2*(1+0.4/2*L$20^2) -> 1.1460698
A24: 3000 | B24: =$E5/$E$2*(1+0.4/2*B$20^2) -> 0.93250043 | C24: =$E5/$E$2*(1+0.4/2*C$20^2) -> 0.93436543 | D24: =$E5/$E$2*(1+0.4/2*D$20^2) -> 0.93996044 | E24: =$E5/$E$2*(1+0.4/2*E$20^2) -> 0.94928544 | F24: =$E5/$E$2*(1+0.4/2*F$20^2) -> 0.96234045 | G24: =$E5/$E$2*(1+0.4/2*G$20^2) -> 0.97912546 | H24: =$E5/$E$2*(1+0.4/2*H$20^2) -> 0.99964047 | I24: =$E5/$E$2*(1+0.4/2*I$20^2) -> 1.0238855 | ... L24: =$E5/$E$2*(1+0.4/2*L$20^2) -> 1.1190005
A25: 4000 | B25: =$E6/$E$2*(1+0.4/2*B$20^2) -> 0.90994274 | C25: =$E6/$E$2*(1+0.4/2*C$20^2) -> 0.91176262 | D25: =$E6/$E$2*(1+0.4/2*D$20^2) -> 0.91722228 | E25: =$E6/$E$2*(1+0.4/2*E$20^2) -> 0.92632171 | F25: =$E6/$E$2*(1+0.4/2*F$20^2) -> 0.93906091 | G25: =$E6/$E$2*(1+0.4/2*G$20^2) -> 0.95543988 | H25: =$E6/$E$2*(1+0.4/2*H$20^2) -> 0.97545862 | I25: =$E6/$E$2*(1+0.4/2*I$20^2) -> 0.99911713 | ... L25: =$E6/$E$2*(1+0.4/2*L$20^2) -> 1.0919313
A26: 5000 | B26: =$E7/$E$2*(1+0.4/2*B$20^2) -> 0.88738504 | C26: =$E7/$E$2*(1+0.4/2*C$20^2) -> 0.88915981 | D26: =$E7/$E$2*(1+0.4/2*D$20^2) -> 0.89448412 | E26: =$E7/$E$2*(1+0.4/2*E$20^2) -> 0.90335797 | F26: =$E7/$E$2*(1+0.4/2*F$20^2) -> 0.91578136 | G26: =$E7/$E$2*(1+0.4/2*G$20^2) -> 0.93175429 | H26: =$E7/$E$2*(1+0.4/2*H$20^2) -> 0.95127677 | I26: =$E7/$E$2*(1+0.4/2*I$20^2) -> 0.97434878 | ... L26: =$E7/$E$2*(1+0.4/2*L$20^2) -> 1.0648621
A27: 6000 | B27: =$E8/$E$2*(1+0.4/2*B$20^2) -> 0.86482735 | C27: =$E8/$E$2*(1+0.4/2*C$20^2) -> 0.866557 | D27: =$E8/$E$2*(1+0.4/2*D$20^2) -> 0.87174597 | E27: =$E8/$E$2*(1+0.4/2*E$20^2) -> 0.88039424 | F27: =$E8/$E$2*(1+0.4/2*F$20^2) -> 0.89250182 | G27: =$E8/$E$2*(1+0.4/2*G$20^2) -> 0.90806871 | H27: =$E8/$E$2*(1+0.4/2*H$20^2) -> 0.92709492 | I27: =$E8/$E$2*(1+0.4/2*I$20^2) -> 0.94958043 | ... L27: =$E8/$E$2*(1+0.4/2*L$20^2) -> 1.0377928
A28: 7000 | B28: =$E9/$E$2*(1+0.4/2*B$20^2) -> 0.84226965 | C28: =$E9/$E$2*(1+0.4/2*C$20^2) -> 0.84395419 | D28: =$E9/$E$2*(1+0.4/2*D$20^2) -> 0.84900781 | E28: =$E9/$E$2*(1+0.4/2*E$20^2) -> 0.8574305 | F28: =$E9/$E$2*(1+0.4/2*F$20^2) -> 0.86922228 | G28: =$E9/$E$2*(1+0.4/2*G$20^2) -> 0.88438313 | H28: =$E9/$E$2*(1+0.4/2*H$20^2) -> 0.90291307 | I28: =$E9/$E$2*(1+0.4/2*I$20^2) -> 0.92481208 | ... L28: =$E9/$E$2*(1+0.4/2*L$20^2) -> 1.0107236
A29: 8000 | B29: =$E10/$E$2*(1+0.4/2*B$20^2) -> 0.81971196 | C29: =$E10/$E$2*(1+0.4/2*C$20^2) -> 0.82135138 | D29: =$E10/$E$2*(1+0.4/2*D$20^2) -> 0.82626965 | E29: =$E10/$E$2*(1+0.4/2*E$20^2) -> 0.83446677 | F29: =$E10/$E$2*(1+0.4/2*F$20^2) -> 0.84594274 | G29: =$E10/$E$2*(1+0.4/2*G$20^2) -> 0.86069755 | H29: =$E10/$E$2*(1+0.4/2*H$20^2) -> 0.87873122 | I29: =$E10/$E$2*(1+0.4/2*I$20^2) -> 0.90004373 | ... L29: =$E10/$E$2*(1+0.4/2*L$20^2) -> 0.98365435
A30: 9000 | B30: =$E11/$E$2*(1+0.4/2*B$20^2) -> 0.79715426 | C30: =$E11/$E$2*(1+0.4/2*C$20^2) -> 0.79874857 | D30: =$E11/$E$2*(1+0.4/2*D$20^2) -> 0.80353149 | E30: =$E11/$E$2*(1+0.4/2*E$20^2) -> 0.81150304 | F30: =$E11/$E$2*(1+0.4/2*F$20^2) -> 0.8226632 | G30: =$E11/$E$2*(1+0.4/2*G$20^2) -> 0.83701197 | H30: =$E11/$E$2*(1+0.4/2*H$20^2) -> 0.85454937 | I30: =$E11/$E$2*(1+0.4/2*I$20^2) -> 0.87527538 | ... L30: =$E11/$E$2*(1+0.4/2*L$20^2) -> 0.95658511
A31: 10000 | B31: =$E12/$E$2*(1+0.4/2*B$20^2) -> 0.77494361 | C31: =$E12/$E$2*(1+0.4/2*C$20^2) -> 0.77649349 | D31: =$E12/$E$2*(1+0.4/2*D$20^2) -> 0.78114315 | E31: =$E12/$E$2*(1+0.4/2*E$20^2) -> 0.78889259 | F31: =$E12/$E$2*(1+0.4/2*F$20^2) -> 0.7997418 | G31: =$E12/$E$2*(1+0.4/2*G$20^2) -> 0.81369079 | H31: =$E12/$E$2*(1+0.4/2*H$20^2) -> 0.83073955 | I31: =$E12/$E$2*(1+0.4/2*I$20^2) -> 0.85088808 | ... L31: =$E12/$E$2*(1+0.4/2*L$20^2) -> 0.92993233
A34: sig0 | B34: Mach
B35: 0 | C35: 0.1 | D35: 0.2 | E35: 0.3 | F35: 0.4 | G35: 0.5 | H35: 0.6 | I35: 0.7 | J35: 0.8 | K35: 0.9 | L35: 1
A36: 0 | B36: =$F2/$F$2*(1+0.4/2*B$35^2)*(1.4/(1.4-1)) -> 3.5 | C36: =$F2/$F$2*(1+0.4/2*C$35^2)*(1.4/(1.4-1)) -> 3.507 | D36: =$F2/$F$2*(1+0.4/2*D$35^2)*(1.4/(1.4-1)) -> 3.528 | E36: =$F2/$F$2*(1+0.4/2*E$35^2)*(1.4/(1.4-1)) -> 3.563 | F36: =$F2/$F$2*(1+0.4/2*F$35^2)*(1.4/(1.4-1)) -> 3.612 | G36: =$F2/$F$2*(1+0.4/2*G$35^2)*(1.4/(1.4-1)) -> 3.675 | H36: =$F2/$F$2*(1+0.4/2*H$35^2)*(1.4/(1.4-1)) -> 3.752 | I36: =$F2/$F$2*(1+0.4/2*I$35^2)*(1.4/(1.4-1)) -> 3.843 | ... L36: =$F2/$F$2*(1+0.4/2*L$35^2)*(1.4/(1.4-1)) -> 4.2 | M36: Altitude
A37: 1000 | B37: =$F3/$F$2*(1+0.4/2*B$35^2)*(1.4/(1.4-1)) -> 3.1054294 | C37: =$F3/$F$2*(1+0.4/2*C$35^2)*(1.4/(1.4-1)) -> 3.1116403 | D37: =$F3/$F$2*(1+0.4/2*D$35^2)*(1.4/(1.4-1)) -> 3.1302729 | E37: =$F3/$F$2*(1+0.4/2*E$35^2)*(1.4/(1.4-1)) -> 3.1613271 | F37: =$F3/$F$2*(1+0.4/2*F$35^2)*(1.4/(1.4-1)) -> 3.2048032 | G37: =$F3/$F$2*(1+0.4/2*G$35^2)*(1.4/(1.4-1)) -> 3.2607009 | H37: =$F3/$F$2*(1+0.4/2*H$35^2)*(1.4/(1.4-1)) -> 3.3290203 | I37: =$F3/$F$2*(1+0.4/2*I$35^2)*(1.4/(1.4-1)) -> 3.4097615 | ... L37: =$F3/$F$2*(1+0.4/2*L$35^2)*(1.4/(1.4-1)) -> 3.7265153
A38: 2000 | B38: =$F4/$F$2*(1+0.4/2*B$35^2)*(1.4/(1.4-1)) -> 2.7467917 | C38: =$F4/$F$2*(1+0.4/2*C$35^2)*(1.4/(1.4-1)) -> 2.7522853 | D38: =$F4/$F$2*(1+0.4/2*D$35^2)*(1.4/(1.4-1)) -> 2.768766 | E38: =$F4/$F$2*(1+0.4/2*E$35^2)*(1.4/(1.4-1)) -> 2.796234 | F38: =$F4/$F$2*(1+0.4/2*F$35^2)*(1.4/(1.4-1)) -> 2.834689 | G38: =$F4/$F$2*(1+0.4/2*G$35^2)*(1.4/(1.4-1)) -> 2.8841313 | H38: =$F4/$F$2*(1+0.4/2*H$35^2)*(1.4/(1.4-1)) -> 2.9445607 | I38: =$F4/$F$2*(1+0.4/2*I$35^2)*(1.4/(1.4-1)) -> 3.0159773 | ... L38: =$F4/$F$2*(1+0.4/2*L$35^2)*(1.4/(1.4-1)) -> 3.29615
A39: 3000 | B39: =$F5/$F$2*(1+0.4/2*B$35^2)*(1.4/(1.4-1)) -> 2.4227048 | C39: =$F5/$F$2*(1+0.4/2*C$35^2)*(1.4/(1.4-1)) -> 2.4275502 | D39: =$F5/$F$2*(1+0.4/2*D$35^2)*(1.4/(1.4-1)) -> 2.4420865 | E39: =$F5/$F$2*(1+0.4/2*E$35^2)*(1.4/(1.4-1)) -> 2.4663135 | F39: =$F5/$F$2*(1+0.4/2*F$35^2)*(1.4/(1.4-1)) -> 2.5002314 | G39: =$F5/$F$2*(1+0.4/2*G$35^2)*(1.4/(1.4-1)) -> 2.5438401 | H39: =$F5/$F$2*(1+0.4/2*H$35^2)*(1.4/(1.4-1)) -> 2.5971396 | I39: =$F5/$F$2*(1+0.4/2*I$35^2)*(1.4/(1.4-1)) -> 2.6601299 | ... L39: =$F5/$F$2*(1+0.4/2*L$35^2)*(1.4/(1.4-1)) -> 2.9072458
A40: 4000 | B40: =$F6/$F$2*(1+0.4/2*B$35^2)*(1.4/(1.4-1)) -> 2.1304047 | C40: =$F6/$F$2*(1+0.4/2*C$35^2)*(1.4/(1.4-1)) -> 2.1346655 | D40: =$F6/$F$2*(1+0.4/2*D$35^2)*(1.4/(1.4-1)) -> 2.147448 | E40: =$F6/$F$2*(1+0.4/2*E$35^2)*(1.4/(1.4-1)) -> 2.168752 | F40: =$F6/$F$2*(1+0.4/2*F$35^2)*(1.4/(1.4-1)) -> 2.1985777 | G40: =$F6/$F$2*(1+0.4/2*G$35^2)*(1.4/(1.4-1)) -> 2.236925 | H40: =$F6/$F$2*(1+0.4/2*H$35^2)*(1.4/(1.4-1)) -> 2.2837939 | I40: =$F6/$F$2*(1+0.4/2*I$35^2)*(1.4/(1.4-1)) -> 2.3391844 | ... L40: =$F6/$F$2*(1+0.4/2*L$35^2)*(1.4/(1.4-1)) -> 2.5564857
A41: 5000 | B41: =$F7/$F$2*(1+0.4/2*B$35^2)*(1.4/(1.4-1)) -> 1.8674729 | C41: =$F7/$F$2*(1+0.4/2*C$35^2)*(1.4/(1.4-1)) -> 1.8712078 | D41: =$F7/$F$2*(1+0.4/2*D$35^2)*(1.4/(1.4-1)) -> 1.8824126 | E41: =$F7/$F$2*(1+0.4/2*E$35^2)*(1.4/(1.4-1)) -> 1.9010874 | F41: =$F7/$F$2*(1+0.4/2*F$35^2)*(1.4/(1.4-1)) -> 1.927232 | G41: =$F7/$F$2*(1+0.4/2*G$35^2)*(1.4/(1.4-1)) -> 1.9608465 | H41: =$F7/$F$2*(1+0.4/2*H$35^2)*(1.4/(1.4-1)) -> 2.0019309 | I41: =$F7/$F$2*(1+0.4/2*I$35^2)*(1.4/(1.4-1)) -> 2.0504852 | ... L41: =$F7/$F$2*(1+0.4/2*L$35^2)*(1.4/(1.4-1)) -> 2.2409674
A42: 6000 | B42: =$F8/$F$2*(1+0.4/2*B$35^2)*(1.4/(1.4-1)) -> 1.6314906 | C42: =$F8/$F$2*(1+0.4/2*C$35^2)*(1.4/(1.4-1)) -> 1.6347536 | D42: =$F8/$F$2*(1+0.4/2*D$35^2)*(1.4/(1.4-1)) -> 1.6445425 | E42: =$F8/$F$2*(1+0.4/2*E$35^2)*(1.4/(1.4-1)) -> 1.6608575 | F42: =$F8/$F$2*(1+0.4/2*F$35^2)*(1.4/(1.4-1)) -> 1.6836983 | G42: =$F8/$F$2*(1+0.4/2*G$35^2)*(1.4/(1.4-1)) -> 1.7130652 | H42: =$F8/$F$2*(1+0.4/2*H$35^2)*(1.4/(1.4-1)) -> 1.7489579 | I42: =$F8/$F$2*(1+0.4/2*I$35^2)*(1.4/(1.4-1)) -> 1.7913767 | ... L42: =$F8/$F$2*(1+0.4/2*L$35^2)*(1.4/(1.4-1)) -> 1.9577887
A43: 7000 | B43: =$F9/$F$2*(1+0.4/2*B$35^2)*(1.4/(1.4-1)) -> 1.420385 | C43: =$F9/$F$2*(1+0.4/2*C$35^2)*(1.4/(1.4-1)) -> 1.4232258 | D43: =$F9/$F$2*(1+0.4/2*D$35^2)*(1.4/(1.4-1)) -> 1.4317481 | E43: =$F9/$F$2*(1+0.4/2*E$35^2)*(1.4/(1.4-1)) -> 1.4459519 | F43: =$F9/$F$2*(1+0.4/2*F$35^2)*(1.4/(1.4-1)) -> 1.4658373 | G43: =$F9/$F$2*(1+0.4/2*G$35^2)*(1.4/(1.4-1)) -> 1.4914042 | H43: =$F9/$F$2*(1+0.4/2*H$35^2)*(1.4/(1.4-1)) -> 1.5226527 | I43: =$F9/$F$2*(1+0.4/2*I$35^2)*(1.4/(1.4-1)) -> 1.5595827 | ... L43: =$F9/$F$2*(1+0.4/2*L$35^2)*(1.4/(1.4-1)) -> 1.704462
...

Sheet Sheet4
A1: TR | B1: W | D1: V | E1: Mach | R1: Mach | S1: a | U1: Altitude | V1: Temp | W1: Pressure | X1: Density
A2: 0.5 | B2: =65000*9.81*0.9 -> 573885 | D2: a | E2: 0.001 | F2: 0.1 | G2: 0.2 | H2: 0.3 | I2: 0.4 | J2: 0.5 | K2: 0.6 | L2: 0.7 | M2: 0.8 | N2: 0.9 | O2: 1 | R2: 0 | S2: 340.3 | U2: 0 | V2: 288.15 | W2: 9.807 | X2: 1.225
A3: S | B3: CD0 | C3: k | D3: 340.3 | E3: =$D3*E$2 -> 0.3403 | F3: =$D3*F$2 -> 34.03 | G3: =$D3*G$2 -> 68.06 | H3: =$D3*H$2 -> 102.09 | I3: =$D3*I$2 -> 136.12 | J3: =$D3*J$2 -> 170.15 | K3: =$D3*K$2 -> 204.18 | L3: =$D3*L$2 -> 238.21 | ... O3: =$D3*O$2 -> 340.3 | P3: Altitude | R3: 0.1 | S3: 336.4 | U3: 1000 | V3: 281.7 | W3: 0.9075 | X3: 1.112
A4: ='A320 Wing'!B3 -> 124.02 | B4: ='A320 Wing'!A50 -> 0.027 | C4: ='A320 Wing'!B50 -> 0.039430145 | D4: 336.4 | E4: =$D4*E$2 -> 0.3364 | F4: =$D4*F$2 -> 33.64 | G4: =$D4*G$2 -> 67.28 | H4: =$D4*H$2 -> 100.92 | I4: =$D4*I$2 -> 134.56 | J4: =$D4*J$2 -> 168.2 | K4: =$D4*K$2 -> 201.84 | L4: =$D4*L$2 -> 235.48 | ... O4: =$D4*O$2 -> 336.4 | R4: 0.2 | S4: 332.5 | U4: 2000 | V4: 275.2 | W4: 0.8217 | X4: 1.007
C5: k | D5: 332.5 | E5: =$D5*E$2 -> 0.3325 | F5: =$D5*F$2 -> 33.25 | G5: =$D5*G$2 -> 66.5 | H5: =$D5*H$2 -> 99.75 | I5: =$D5*I$2 -> 133 | J5: =$D5*J$2 -> 166.25 | K5: =$D5*K$2 -> 199.5 | L5: =$D5*L$2 -> 232.75 | ... O5: =$D5*O$2 -> 332.5 | R5: 0.3 | S5: 328.6 | U5: 3000 | V5: 268.7 | W5: 0.7423 | X5: 0.9093
A6: TSL | C6: =0.075 -> 0.075 | D6: 328.6 | E6: =$D6*E$2 -> 0.3286 | F6: =$D6*F$2 -> 32.86 | G6: =$D6*G$2 -> 65.72 | H6: =$D6*H$2 -> 98.58 | I6: =$D6*I$2 -> 131.44 | J6: =$D6*J$2 -> 164.3 | K6: =$D6*K$2 -> 197.16 | L6: =$D6*L$2 -> 230.02 | ... O6: =$D6*O$2 -> 328.6 | R6: 0.4 | S6: 324.6 | U6: 4000 | V6: 262.2 | W6: 0.6689 | X6: 0.8194
A7: ='Engine Deck'!I2*1 -> 105000 | D7: 324.6 | E7: =$D7*E$2 -> 0.3246 | F7: =$D7*F$2 -> 32.46 | G7: =$D7*G$2 -> 64.92 | H7: =$D7*H$2 -> 97.38 | I7: =$D7*I$2 -> 129.84 | J7: =$D7*J$2 -> 162.3 | K7: =$D7*K$2 -> 194.76 | L7: =$D7*L$2 -> 227.22 | ... O7: =$D7*O$2 -> 324.6 | R7: 0.5 | S7: 320.5 | U7: 5000 | V7: 255.7 | W7: 0.6012 | X7: 0.7364
D8: 320.5 | E8: =$D8*E$2 -> 0.3205 | F8: =$D8*F$2 -> 32.05 | G8: =$D8*G$2 -> 64.1 | H8: =$D8*H$2 -> 96.15 | I8: =$D8*I$2 -> 128.2 | J8: =$D8*J$2 -> 160.25 | K8: =$D8*K$2 -> 192.3 | L8: =$D8*L$2 -> 224.35 | ... O8: =$D8*O$2 -> 320.5 | R8: 0.6 | S8: 316.5 | U8: 6000 | V8: 249.2 | W8: 0.5389 | X8: 0.6601
A9: clMAX | D9: 316.5 | E9: =$D9*E$2 -> 0.3165 | F9: =$D9*F$2 -> 31.65 | G9: =$D9*G$2 -> 63.3 | H9: =$D9*H$2 -> 94.95 | I9: =$D9*I$2 -> 126.6 | J9: =$D9*J$2 -> 158.25 | K9: =$D9*K$2 -> 189.9 | L9: =$D9*L$2 -> 221.55 | ... O9: =$D9*O$2 -> 316.5 | R9: 0.7 | S9: 312.3 | U9: 7000 | V9: 242.7 | W9: 0.4817 | X9: 0.59
A10: 2.1 | D10: 312.3 | E10: =$D10*E$2 -> 0.3123 | F10: =$D10*F$2 -> 31.23 | G10: =$D10*G$2 -> 62.46 | H10: =$D10*H$2 -> 93.69 | I10: =$D10*I$2 -> 124.92 | J10: =$D10*J$2 -> 156.15 | K10: =$D10*K$2 -> 187.38 | L10: =$D10*L$2 -> 218.61 | ... O10: =$D10*O$2 -> 312.3 | R10: 0.8 | S10: 308.1 | U10: 8000 | V10: 236.2 | W10: 0.4292 | X10: 0.5258
D11: 308.1 | E11: =$D11*E$2 -> 0.3081 | F11: =$D11*F$2 -> 30.81 | G11: =$D11*G$2 -> 61.62 | H11: =$D11*H$2 -> 92.43 | I11: =$D11*I$2 -> 123.24 | J11: =$D11*J$2 -> 154.05 | K11: =$D11*K$2 -> 184.86 | L11: =$D11*L$2 -> 215.67 | ... O11: =$D11*O$2 -> 308.1 | R11: 0.9 | S11: 303.8 | U11: 9000 | V11: 229.7 | W11: 0.3813 | X11: 0.4671
D12: 303.8 | E12: =$D12*E$2 -> 0.3038 | F12: =$D12*F$2 -> 30.38 | G12: =$D12*G$2 -> 60.76 | H12: =$D12*H$2 -> 91.14 | I12: =$D12*I$2 -> 121.52 | J12: =$D12*J$2 -> 151.9 | K12: =$D12*K$2 -> 182.28 | L12: =$D12*L$2 -> 212.66 | ... O12: =$D12*O$2 -> 303.8 | R12: 1 | S12: 299.5 | U12: 10000 | V12: 223.3 | W12: 0.3376 | X12: 0.4135
D13: 299.5 | E13: =$D13*E$2 -> 0.2995 | F13: =$D13*F$2 -> 29.95 | G13: =$D13*G$2 -> 59.9 | H13: =$D13*H$2 -> 89.85 | I13: =$D13*I$2 -> 119.8 | J13: =$D13*J$2 -> 149.75 | K13: =$D13*K$2 -> 179.7 | L13: =$D13*L$2 -> 209.65 | ... O13: =$D13*O$2 -> 299.5
C14: CL | D14: Mach | E14: 0.05 | F14: 0.1 | G14: 0.2 | H14: 0.3 | I14: 0.4 | J14: 0.5 | K14: 0.6 | L14: 0.7 | M14: 0.8 | N14: 0.9 | O14: 1
C15: density | D15: a | E15: 340.3 | F15: 336.4 | G15: 332.5 | H15: 328.6 | I15: 324.6 | J15: 320.5 | K15: 316.5 | L15: 312.3 | M15: 308.1 | N15: 303.8 | O15: 299.5
C16: 1.225 | D16: 0 | E16: =$B$2/(1/2*$C16*(E3+0.001)^2*$A$4) -> 64856.645 | F16: =$B$2/(1/2*$C16*(F3+0.001)^2*$A$4) -> 6.5234544 | G16: =$B$2/(1/2*$C16*(G3+0.001)^2*$A$4) -> 1.6309115 | H16: =$B$2/(1/2*$C16*(H3+0.001)^2*$A$4) -> 0.72485667 | I16: =$B$2/(1/2*$C16*(I3+0.001)^2*$A$4) -> 0.40773387 | J16: =$B$2/(1/2*$C16*(J3+0.001)^2*$A$4) -> 0.26095044 | K16: =$B$2/(1/2*$C16*(K3+0.001)^2*$A$4) -> 0.18121594 | L16: =$B$2/(1/2*$C16*(L3+0.001)^2*$A$4) -> 0.13313843 | ... O16: =$B$2/(1/2*$C16*(O3+0.001)^2*$A$4) -> 0.065237995 | P16: Altitude
C17: 1.112 | D17: 1000 | E17: =$B$2/(1/2*$C17*(E4+0.001)^2*$A$4) -> 73108.555 | F17: =$B$2/(1/2*$C17*(F4+0.001)^2*$A$4) -> 7.3539481 | G17: =$B$2/(1/2*$C17*(G4+0.001)^2*$A$4) -> 1.8385417 | H17: =$B$2/(1/2*$C17*(H4+0.001)^2*$A$4) -> 0.81713773 | I17: =$B$2/(1/2*$C17*(I4+0.001)^2*$A$4) -> 0.45964225 | J17: =$B$2/(1/2*$C17*(J4+0.001)^2*$A$4) -> 0.29417192 | K17: =$B$2/(1/2*$C17*(K4+0.001)^2*$A$4) -> 0.20428646 | L17: =$B$2/(1/2*$C17*(L4+0.001)^2*$A$4) -> 0.15008822 | ... O17: =$B$2/(1/2*$C17*(O4+0.001)^2*$A$4) -> 0.073543416
C18: 1.007 | D18: 2000 | E18: =$B$2/(1/2*$C18*(E5+0.001)^2*$A$4) -> 82630.807 | F18: =$B$2/(1/2*$C18*(F5+0.001)^2*$A$4) -> 8.3123582 | G18: =$B$2/(1/2*$C18*(G5+0.001)^2*$A$4) -> 2.078152 | H18: =$B$2/(1/2*$C18*(H5+0.001)^2*$A$4) -> 0.92363239 | I18: =$B$2/(1/2*$C18*(I5+0.001)^2*$A$4) -> 0.51954582 | J18: =$B$2/(1/2*$C18*(J5+0.001)^2*$A$4) -> 0.33251033 | K18: =$B$2/(1/2*$C18*(K5+0.001)^2*$A$4) -> 0.23091041 | L18: =$B$2/(1/2*$C18*(L5+0.001)^2*$A$4) -> 0.16964871 | ... O18: =$B$2/(1/2*$C18*(O5+0.001)^2*$A$4) -> 0.083128082
C19: 0.9093 | D19: 3000 | E19: =$B$2/(1/2*$C19*(E6+0.001)^2*$A$4) -> 93687.477 | F19: =$B$2/(1/2*$C19*(F6+0.001)^2*$A$4) -> 9.425283 | G19: =$B$2/(1/2*$C19*(G6+0.001)^2*$A$4) -> 2.3563925 | H19: =$B$2/(1/2*$C19*(H6+0.001)^2*$A$4) -> 1.0472962 | I19: =$B$2/(1/2*$C19*(I6+0.001)^2*$A$4) -> 0.58910708 | J19: =$B$2/(1/2*$C19*(J6+0.001)^2*$A$4) -> 0.37702968 | K19: =$B$2/(1/2*$C19*(K6+0.001)^2*$A$4) -> 0.2618267 | L19: =$B$2/(1/2*$C19*(L6+0.001)^2*$A$4) -> 0.19236275 | ... O19: =$B$2/(1/2*$C19*(O6+0.001)^2*$A$4) -> 0.094257993
C20: 0.8194 | D20: 4000 | E20: =$B$2/(1/2*$C20*(E7+0.001)^2*$A$4) -> 106536.49 | F20: =$B$2/(1/2*$C20*(F7+0.001)^2*$A$4) -> 10.718732 | G20: =$B$2/(1/2*$C20*(G7+0.001)^2*$A$4) -> 2.6797654 | H20: =$B$2/(1/2*$C20*(H7+0.001)^2*$A$4) -> 1.1910191 | I20: =$B$2/(1/2*$C20*(I7+0.001)^2*$A$4) -> 0.66995168 | J20: =$B$2/(1/2*$C20*(J7+0.001)^2*$A$4) -> 0.42877039 | K20: =$B$2/(1/2*$C20*(K7+0.001)^2*$A$4) -> 0.29775783 | L20: =$B$2/(1/2*$C20*(L7+0.001)^2*$A$4) -> 0.21876118 | ... O20: =$B$2/(1/2*$C20*(O7+0.001)^2*$A$4) -> 0.10719326
C21: 0.7364 | D21: 5000 | E21: =$B$2/(1/2*$C21*(E8+0.001)^2*$A$4) -> 121587.07 | F21: =$B$2/(1/2*$C21*(F8+0.001)^2*$A$4) -> 12.233936 | G21: =$B$2/(1/2*$C21*(G8+0.001)^2*$A$4) -> 3.0585794 | H21: =$B$2/(1/2*$C21*(H8+0.001)^2*$A$4) -> 1.3593827 | I21: =$B$2/(1/2*$C21*(I8+0.001)^2*$A$4) -> 0.76465677 | J21: =$B$2/(1/2*$C21*(J8+0.001)^2*$A$4) -> 0.48938186 | K21: =$B$2/(1/2*$C21*(K8+0.001)^2*$A$4) -> 0.33984922 | L21: =$B$2/(1/2*$C21*(L8+0.001)^2*$A$4) -> 0.24968551 | ... O21: =$B$2/(1/2*$C21*(O8+0.001)^2*$A$4) -> 0.12234623
C22: 0.6601 | D22: 6000 | E22: =$B$2/(1/2*$C22*(E9+0.001)^2*$A$4) -> 139080.41 | F22: =$B$2/(1/2*$C22*(F9+0.001)^2*$A$4) -> 13.995182 | G22: =$B$2/(1/2*$C22*(G9+0.001)^2*$A$4) -> 3.4989059 | H22: =$B$2/(1/2*$C22*(H9+0.001)^2*$A$4) -> 1.5550857 | I22: =$B$2/(1/2*$C22*(I9+0.001)^2*$A$4) -> 0.8747403 | J22: =$B$2/(1/2*$C22*(J9+0.001)^2*$A$4) -> 0.55983556 | K22: =$B$2/(1/2*$C22*(K9+0.001)^2*$A$4) -> 0.38877552 | L22: =$B$2/(1/2*$C22*(L9+0.001)^2*$A$4) -> 0.28563142 | ... O22: =$B$2/(1/2*$C22*(O9+0.001)^2*$A$4) -> 0.13995978
C23: 0.59 | D23: 7000 | E23: =$B$2/(1/2*$C23*(E10+0.001)^2*$A$4) -> 159804.99 | F23: =$B$2/(1/2*$C23*(F10+0.001)^2*$A$4) -> 16.081974 | G23: =$B$2/(1/2*$C23*(G10+0.001)^2*$A$4) -> 4.0206222 | H23: =$B$2/(1/2*$C23*(H10+0.001)^2*$A$4) -> 1.7869623 | I23: =$B$2/(1/2*$C23*(I10+0.001)^2*$A$4) -> 1.0051716 | J23: =$B$2/(1/2*$C23*(J10+0.001)^2*$A$4) -> 0.64331191 | K23: =$B$2/(1/2*$C23*(K10+0.001)^2*$A$4) -> 0.44674533 | L23: =$B$2/(1/2*$C23*(L10+0.001)^2*$A$4) -> 0.32822156 | ... O23: =$B$2/(1/2*$C23*(O10+0.001)^2*$A$4) -> 0.16082901
C24: 0.5258 | D24: 8000 | E24: =$B$2/(1/2*$C24*(E11+0.001)^2*$A$4) -> 184223.3 | F24: =$B$2/(1/2*$C24*(F11+0.001)^2*$A$4) -> 18.540907 | G24: =$B$2/(1/2*$C24*(G11+0.001)^2*$A$4) -> 4.6353772 | H24: =$B$2/(1/2*$C24*(H11+0.001)^2*$A$4) -> 2.0601899 | I24: =$B$2/(1/2*$C24*(I11+0.001)^2*$A$4) -> 1.1588631 | J24: =$B$2/(1/2*$C24*(J11+0.001)^2*$A$4) -> 0.74167479 | K24: =$B$2/(1/2*$C24*(K11+0.001)^2*$A$4) -> 0.51505305 | L24: =$B$2/(1/2*$C24*(L11+0.001)^2*$A$4) -> 0.37840691 | ... O24: =$B$2/(1/2*$C24*(O11+0.001)^2*$A$4) -> 0.1854199
C25: 0.4671 | D25: 9000 | E25: =$B$2/(1/2*$C25*(E12+0.001)^2*$A$4) -> 213266.85 | F25: =$B$2/(1/2*$C25*(F12+0.001)^2*$A$4) -> 21.465902 | G25: =$B$2/(1/2*$C25*(G12+0.001)^2*$A$4) -> 5.3666522 | H25: =$B$2/(1/2*$C25*(H12+0.001)^2*$A$4) -> 2.3852049 | I25: =$B$2/(1/2*$C25*(I12+0.001)^2*$A$4) -> 1.3416851 | J25: =$B$2/(1/2*$C25*(J12+0.001)^2*$A$4) -> 0.85868131 | K25: =$B$2/(1/2*$C25*(K12+0.001)^2*$A$4) -> 0.59630777 | L25: =$B$2/(1/2*$C25*(L12+0.001)^2*$A$4) -> 0.43810436 | ... O25: =$B$2/(1/2*$C25*(O12+0.001)^2*$A$4) -> 0.21467174
C26: 0.4135 | D26: 10000 | E26: =$B$2/(1/2*$C26*(E13+0.001)^2*$A$4) -> 247855.57 | F26: =$B$2/(1/2*$C26*(F13+0.001)^2*$A$4) -> 24.94968 | G26: =$B$2/(1/2*$C26*(G13+0.001)^2*$A$4) -> 6.2376282 | H26: =$B$2/(1/2*$C26*(H13+0.001)^2*$A$4) -> 2.77231 | I26: =$B$2/(1/2*$C26*(I13+0.001)^2*$A$4) -> 1.5594331 | J26: =$B$2/(1/2*$C26*(J13+0.001)^2*$A$4) -> 0.9980405 | K26: =$B$2/(1/2*$C26*(K13+0.001)^2*$A$4) -> 0.69308522 | L26: =$B$2/(1/2*$C26*(L13+0.001)^2*$A$4) -> 0.50920628 | ... O26: =$B$2/(1/2*$C26*(O13+0.001)^2*$A$4) -> 0.24951179
C27: Drag | D27: Mach | E27: 0.05 | F27: 0.1 | G27: 0.2 | H27: 0.3 | I27: 0.4 | J27: 0.5 | K27: 0.6 | L27: 0.7 | M27: 0.8 | N27: 0.9 | O27: 1
C28: density | D28: a | E28: 340.3 | F28: 336.4 | G28: 332.5 | H28: 328.6 | I28: 324.6 | J28: 320.5 | K28: 316.5 | L28: 312.3 | M28: 308.1 | N28: 303.8 | O28: 299.5
C29: 1.225 | D29: 0 | E29: =IF(E$27<=0.7,(1/2*$C29*(E3+0.001)^2*$A$4)*($B$4+$C$4*E16^2),(1/2*$C29*(E3+0.001)^2*$A$4)*($B$4+$C$6*E16^2)) -> 1.4676001e+09 | F29: =IF(F$27<=0.7,(1/2*$C29*(F3+0.001)^2*$A$4)*($B$4+$C$4*F16^2),(1/2*$C29*(F3+0.001)^2*$A$4)*($B$4+$C$6*F16^2)) -> 149990.39 | G29: =IF(G$27<=0.7,(1/2*$C29*(G3+0.001)^2*$A$4)*($B$4+$C$4*G16^2),(1/2*$C29*(G3+0.001)^2*$A$4)*($B$4+$C$6*G16^2)) -> 46405.625 | H29: =IF(H$27<=0.7,(1/2*$C29*(H3+0.001)^2*$A$4)*($B$4+$C$4*H16^2),(1/2*$C29*(H3+0.001)^2*$A$4)*($B$4+$C$6*H16^2)) -> 37778.819 | I29: =IF(I$27<=0.7,(1/2*$C29*(I3+0.001)^2*$A$4)*($B$4+$C$4*I16^2),(1/2*$C29*(I3+0.001)^2*$A$4)*($B$4+$C$6*I16^2)) -> 47228.824 | J29: =IF(J$27<=0.7,(1/2*$C29*(J3+0.001)^2*$A$4)*($B$4+$C$4*J16^2),(1/2*$C29*(J3+0.001)^2*$A$4)*($B$4+$C$6*J16^2)) -> 65283.571 | K29: =IF(K$27<=0.7,(1/2*$C29*(K3+0.001)^2*$A$4)*($B$4+$C$4*K16^2),(1/2*$C29*(K3+0.001)^2*$A$4)*($B$4+$C$6*K16^2)) -> 89605.764 | L29: =IF(L$27<=0.7,(1/2*$C29*(L3+0.001)^2*$A$4)*($B$4+$C$4*L16^2),(1/2*$C29*(L3+0.001)^2*$A$4)*($B$4+$C$6*L16^2)) -> 119394.54 | ... O29: =IF(O$27<=0.7,(1/2*$C29*(O3+0.001)^2*$A$4)*($B$4+$C$4*O16^2),(1/2*$C29*(O3+0.001)^2*$A$4)*($B$4+$C$6*O16^2)) -> 240321.29 | P29: Altitude
C30: 1.112 | D30: 1000 | E30: =IF(E$27<=0.7,(1/2*$C30*(E4+0.001)^2*$A$4)*($B$4+$C$4*E17^2),(1/2*$C30*(E4+0.001)^2*$A$4)*($B$4+$C$6*E17^2)) -> 1.6543273e+09 | F30: =IF(F$27<=0.7,(1/2*$C30*(F4+0.001)^2*$A$4)*($B$4+$C$4*F17^2),(1/2*$C30*(F4+0.001)^2*$A$4)*($B$4+$C$6*F17^2)) -> 168514.87 | G30: =IF(G$27<=0.7,(1/2*$C30*(G4+0.001)^2*$A$4)*($B$4+$C$4*G17^2),(1/2*$C30*(G4+0.001)^2*$A$4)*($B$4+$C$6*G17^2)) -> 50031.017 | H30: =IF(H$27<=0.7,(1/2*$C30*(H4+0.001)^2*$A$4)*($B$4+$C$4*H17^2),(1/2*$C30*(H4+0.001)^2*$A$4)*($B$4+$C$6*H17^2)) -> 37452.897 | I30: =IF(I$27<=0.7,(1/2*$C30*(I4+0.001)^2*$A$4)*($B$4+$C$4*I17^2),(1/2*$C30*(I4+0.001)^2*$A$4)*($B$4+$C$6*I17^2)) -> 44111.726 | J30: =IF(J$27<=0.7,(1/2*$C30*(J4+0.001)^2*$A$4)*($B$4+$C$4*J17^2),(1/2*$C30*(J4+0.001)^2*$A$4)*($B$4+$C$6*J17^2)) -> 59329.555 | K30: =IF(K$27<=0.7,(1/2*$C30*(K4+0.001)^2*$A$4)*($B$4+$C$4*K17^2),(1/2*$C30*(K4+0.001)^2*$A$4)*($B$4+$C$6*K17^2)) -> 80471.53 | L30: =IF(L$27<=0.7,(1/2*$C30*(L4+0.001)^2*$A$4)*($B$4+$C$4*L17^2),(1/2*$C30*(L4+0.001)^2*$A$4)*($B$4+$C$6*L17^2)) -> 106634.83 | ... O30: =IF(O$27<=0.7,(1/2*$C30*(O4+0.001)^2*$A$4)*($B$4+$C$4*O17^2),(1/2*$C30*(O4+0.001)^2*$A$4)*($B$4+$C$6*O17^2)) -> 213855.85
C31: 1.007 | D31: 2000 | E31: =IF(E$27<=0.7,(1/2*$C31*(E5+0.001)^2*$A$4)*($B$4+$C$4*E18^2),(1/2*$C31*(E5+0.001)^2*$A$4)*($B$4+$C$6*E18^2)) -> 1.8698004e+09 | F31: =IF(F$27<=0.7,(1/2*$C31*(F5+0.001)^2*$A$4)*($B$4+$C$4*F18^2),(1/2*$C31*(F5+0.001)^2*$A$4)*($B$4+$C$6*F18^2)) -> 189959.18 | G31: =IF(G$27<=0.7,(1/2*$C31*(G5+0.001)^2*$A$4)*($B$4+$C$4*G18^2),(1/2*$C31*(G5+0.001)^2*$A$4)*($B$4+$C$6*G18^2)) -> 54481.283 | H31: =IF(H$27<=0.7,(1/2*$C31*(H5+0.001)^2*$A$4)*($B$4+$C$4*H18^2),(1/2*$C31*(H5+0.001)^2*$A$4)*($B$4+$C$6*H18^2)) -> 37676.335 | I31: =IF(I$27<=0.7,(1/2*$C31*(I5+0.001)^2*$A$4)*($B$4+$C$4*I18^2),(1/2*$C31*(I5+0.001)^2*$A$4)*($B$4+$C$6*I18^2)) -> 41580.398 | J31: =IF(J$27<=0.7,(1/2*$C31*(J5+0.001)^2*$A$4)*($B$4+$C$4*J18^2),(1/2*$C31*(J5+0.001)^2*$A$4)*($B$4+$C$6*J18^2)) -> 54123.907 | K31: =IF(K$27<=0.7,(1/2*$C31*(K5+0.001)^2*$A$4)*($B$4+$C$4*K18^2),(1/2*$C31*(K5+0.001)^2*$A$4)*($B$4+$C$6*K18^2)) -> 72328.618 | L31: =IF(L$27<=0.7,(1/2*$C31*(L5+0.001)^2*$A$4)*($B$4+$C$4*L18^2),(1/2*$C31*(L5+0.001)^2*$A$4)*($B$4+$C$6*L18^2)) -> 95174.051 | ... O31: =IF(O$27<=0.7,(1/2*$C31*(O5+0.001)^2*$A$4)*($B$4+$C$4*O18^2),(1/2*$C31*(O5+0.001)^2*$A$4)*($B$4+$C$6*O18^2)) -> 189975.79
C32: 0.9093 | D32: 3000 | E32: =IF(E$27<=0.7,(1/2*$C32*(E6+0.001)^2*$A$4)*($B$4+$C$4*E19^2),(1/2*$C32*(E6+0.001)^2*$A$4)*($B$4+$C$6*E19^2)) -> 2.1199948e+09 | F32: =IF(F$27<=0.7,(1/2*$C32*(F6+0.001)^2*$A$4)*($B$4+$C$4*F19^2),(1/2*$C32*(F6+0.001)^2*$A$4)*($B$4+$C$6*F19^2)) -> 214922.75 | G32: =IF(G$27<=0.7,(1/2*$C32*(G6+0.001)^2*$A$4)*($B$4+$C$4*G19^2),(1/2*$C32*(G6+0.001)^2*$A$4)*($B$4+$C$6*G19^2)) -> 59897.002 | H32: =IF(H$27<=0.7,(1/2*$C32*(H6+0.001)^2*$A$4)*($B$4+$C$4*H19^2),(1/2*$C32*(H6+0.001)^2*$A$4)*($B$4+$C$6*H19^2)) -> 38493.745 | I32: =IF(I$27<=0.7,(1/2*$C32*(I6+0.001)^2*$A$4)*($B$4+$C$4*I19^2),(1/2*$C32*(I6+0.001)^2*$A$4)*($B$4+$C$6*I19^2)) -> 39632.873 | J32: =IF(J$27<=0.7,(1/2*$C32*(J6+0.001)^2*$A$4)*($B$4+$C$4*J19^2),(1/2*$C32*(J6+0.001)^2*$A$4)*($B$4+$C$6*J19^2)) -> 49628.848 | K32: =IF(K$27<=0.7,(1/2*$C32*(K6+0.001)^2*$A$4)*($B$4+$C$4*K19^2),(1/2*$C32*(K6+0.001)^2*$A$4)*($B$4+$C$6*K19^2)) -> 65104.677 | L32: =IF(L$27<=0.7,(1/2*$C32*(L6+0.001)^2*$A$4)*($B$4+$C$4*L19^2),(1/2*$C32*(L6+0.001)^2*$A$4)*($B$4+$C$6*L19^2)) -> 84903.248 | ... O32: =IF(O$27<=0.7,(1/2*$C32*(O6+0.001)^2*$A$4)*($B$4+$C$4*O19^2),(1/2*$C32*(O6+0.001)^2*$A$4)*($B$4+$C$6*O19^2)) -> 168445.12
C33: 0.8194 | D33: 4000 | E33: =IF(E$27<=0.7,(1/2*$C33*(E7+0.001)^2*$A$4)*($B$4+$C$4*E20^2),(1/2*$C33*(E7+0.001)^2*$A$4)*($B$4+$C$6*E20^2)) -> 2.410747e+09 | F33: =IF(F$27<=0.7,(1/2*$C33*(F7+0.001)^2*$A$4)*($B$4+$C$4*F20^2),(1/2*$C33*(F7+0.001)^2*$A$4)*($B$4+$C$6*F20^2)) -> 243993 | G33: =IF(G$27<=0.7,(1/2*$C33*(G7+0.001)^2*$A$4)*($B$4+$C$4*G20^2),(1/2*$C33*(G7+0.001)^2*$A$4)*($B$4+$C$6*G20^2)) -> 66420.903 | H33: =IF(H$27<=0.7,(1/2*$C33*(H7+0.001)^2*$A$4)*($B$4+$C$4*H20^2),(1/2*$C33*(H7+0.001)^2*$A$4)*($B$4+$C$6*H20^2)) -> 39960.598 | I33: =IF(I$27<=0.7,(1/2*$C33*(I7+0.001)^2*$A$4)*($B$4+$C$4*I20^2),(1/2*$C33*(I7+0.001)^2*$A$4)*($B$4+$C$6*I20^2)) -> 38288.291 | J33: =IF(J$27<=0.7,(1/2*$C33*(J7+0.001)^2*$A$4)*($B$4+$C$4*J20^2),(1/2*$C33*(J7+0.001)^2*$A$4)*($B$4+$C$6*J20^2)) -> 45840.352 | K33: =IF(K$27<=0.7,(1/2*$C33*(K7+0.001)^2*$A$4)*($B$4+$C$4*K20^2),(1/2*$C33*(K7+0.001)^2*$A$4)*($B$4+$C$6*K20^2)) -> 58776.355 | L33: =IF(L$27<=0.7,(1/2*$C33*(L7+0.001)^2*$A$4)*($B$4+$C$4*L20^2),(1/2*$C33*(L7+0.001)^2*$A$4)*($B$4+$C$6*L20^2)) -> 75780.396 | ... O33: =IF(O$27<=0.7,(1/2*$C33*(O7+0.001)^2*$A$4)*($B$4+$C$4*O20^2),(1/2*$C33*(O7+0.001)^2*$A$4)*($B$4+$C$6*O20^2)) -> 149164.77
C34: 0.7364 | D34: 5000 | E34: =IF(E$27<=0.7,(1/2*$C34*(E8+0.001)^2*$A$4)*($B$4+$C$4*E21^2),(1/2*$C34*(E8+0.001)^2*$A$4)*($B$4+$C$6*E21^2)) -> 2.7513171e+09 | F34: =IF(F$27<=0.7,(1/2*$C34*(F8+0.001)^2*$A$4)*($B$4+$C$4*F21^2),(1/2*$C34*(F8+0.001)^2*$A$4)*($B$4+$C$6*F21^2)) -> 278100.56 | G34: =IF(G$27<=0.7,(1/2*$C34*(G8+0.001)^2*$A$4)*($B$4+$C$4*G21^2),(1/2*$C34*(G8+0.001)^2*$A$4)*($B$4+$C$6*G21^2)) -> 74276.704 | H34: =IF(H$27<=0.7,(1/2*$C34*(H8+0.001)^2*$A$4)*($B$4+$C$4*H21^2),(1/2*$C34*(H8+0.001)^2*$A$4)*($B$4+$C$6*H21^2)) -> 42159.092 | I34: =IF(I$27<=0.7,(1/2*$C34*(I8+0.001)^2*$A$4)*($B$4+$C$4*I21^2),(1/2*$C34*(I8+0.001)^2*$A$4)*($B$4+$C$6*I21^2)) -> 37566.792 | J34: =IF(J$27<=0.7,(1/2*$C34*(J8+0.001)^2*$A$4)*($B$4+$C$4*J21^2),(1/2*$C34*(J8+0.001)^2*$A$4)*($B$4+$C$6*J21^2)) -> 42736.09 | K34: =IF(K$27<=0.7,(1/2*$C34*(K8+0.001)^2*$A$4)*($B$4+$C$4*K21^2),(1/2*$C34*(K8+0.001)^2*$A$4)*($B$4+$C$6*K21^2)) -> 53283.673 | L34: =IF(L$27<=0.7,(1/2*$C34*(L8+0.001)^2*$A$4)*($B$4+$C$4*L21^2),(1/2*$C34*(L8+0.001)^2*$A$4)*($B$4+$C$6*L21^2)) -> 67707.621 | ... O34: =IF(O$27<=0.7,(1/2*$C34*(O8+0.001)^2*$A$4)*($B$4+$C$4*O21^2),(1/2*$C34*(O8+0.001)^2*$A$4)*($B$4+$C$6*O21^2)) -> 131913.87
C35: 0.6601 | D35: 6000 | E35: =IF(E$27<=0.7,(1/2*$C35*(E9+0.001)^2*$A$4)*($B$4+$C$4*E22^2),(1/2*$C35*(E9+0.001)^2*$A$4)*($B$4+$C$6*E22^2)) -> 3.1471627e+09 | F35: =IF(F$27<=0.7,(1/2*$C35*(F9+0.001)^2*$A$4)*($B$4+$C$4*F22^2),(1/2*$C35*(F9+0.001)^2*$A$4)*($B$4+$C$6*F22^2)) -> 317795.29 | G35: =IF(G$27<=0.7,(1/2*$C35*(G9+0.001)^2*$A$4)*($B$4+$C$4*G22^2),(1/2*$C35*(G9+0.001)^2*$A$4)*($B$4+$C$6*G22^2)) -> 83603.03 | H35: =IF(H$27<=0.7,(1/2*$C35*(H9+0.001)^2*$A$4)*($B$4+$C$4*H22^2),(1/2*$C35*(H9+0.001)^2*$A$4)*($B$4+$C$6*H22^2)) -> 45153.066 | I35: =IF(I$27<=0.7,(1/2*$C35*(I9+0.001)^2*$A$4)*($B$4+$C$4*I22^2),(1/2*$C35*(I9+0.001)^2*$A$4)*($B$4+$C$6*I22^2)) -> 37507.655 | J35: =IF(J$27<=0.7,(1/2*$C35*(J9+0.001)^2*$A$4)*($B$4+$C$4*J22^2),(1/2*$C35*(J9+0.001)^2*$A$4)*($B$4+$C$6*J22^2)) -> 40345.748 | K35: =IF(K$27<=0.7,(1/2*$C35*(K9+0.001)^2*$A$4)*($B$4+$C$4*K22^2),(1/2*$C35*(K9+0.001)^2*$A$4)*($B$4+$C$6*K22^2)) -> 48652.991 | L35: =IF(L$27<=0.7,(1/2*$C35*(L9+0.001)^2*$A$4)*($B$4+$C$4*L22^2),(1/2*$C35*(L9+0.001)^2*$A$4)*($B$4+$C$6*L22^2)) -> 60711.239 | ... O35: =IF(O$27<=0.7,(1/2*$C35*(O9+0.001)^2*$A$4)*($B$4+$C$4*O22^2),(1/2*$C35*(O9+0.001)^2*$A$4)*($B$4+$C$6*O22^2)) -> 116733.69
C36: 0.59 | D36: 7000 | E36: =IF(E$27<=0.7,(1/2*$C36*(E10+0.001)^2*$A$4)*($B$4+$C$4*E23^2),(1/2*$C36*(E10+0.001)^2*$A$4)*($B$4+$C$6*E23^2)) -> 3.6161262e+09 | F36: =IF(F$27<=0.7,(1/2*$C36*(F10+0.001)^2*$A$4)*($B$4+$C$4*F23^2),(1/2*$C36*(F10+0.001)^2*$A$4)*($B$4+$C$6*F23^2)) -> 364872.32 | G36: =IF(G$27<=0.7,(1/2*$C36*(G10+0.001)^2*$A$4)*($B$4+$C$4*G23^2),(1/2*$C36*(G10+0.001)^2*$A$4)*($B$4+$C$6*G23^2)) -> 94833.976 | H36: =IF(H$27<=0.7,(1/2*$C36*(H10+0.001)^2*$A$4)*($B$4+$C$4*H23^2),(1/2*$C36*(H10+0.001)^2*$A$4)*($B$4+$C$6*H23^2)) -> 49107.122 | I36: =IF(I$27<=0.7,(1/2*$C36*(I10+0.001)^2*$A$4)*($B$4+$C$4*I23^2),(1/2*$C36*(I10+0.001)^2*$A$4)*($B$4+$C$6*I23^2)) -> 38160.568 | J36: =IF(J$27<=0.7,(1/2*$C36*(J10+0.001)^2*$A$4)*($B$4+$C$4*J23^2),(1/2*$C36*(J10+0.001)^2*$A$4)*($B$4+$C$6*J23^2)) -> 38643.23 | K36: =IF(K$27<=0.7,(1/2*$C36*(K10+0.001)^2*$A$4)*($B$4+$C$4*K23^2),(1/2*$C36*(K10+0.001)^2*$A$4)*($B$4+$C$6*K23^2)) -> 44793.073 | L36: =IF(L$27<=0.7,(1/2*$C36*(L10+0.001)^2*$A$4)*($B$4+$C$4*L23^2),(1/2*$C36*(L10+0.001)^2*$A$4)*($B$4+$C$6*L23^2)) -> 54635.763 | ... O36: =IF(O$27<=0.7,(1/2*$C36*(O10+0.001)^2*$A$4)*($B$4+$C$4*O23^2),(1/2*$C36*(O10+0.001)^2*$A$4)*($B$4+$C$6*O23^2)) -> 103266.21
C37: 0.5258 | D37: 8000 | E37: =IF(E$27<=0.7,(1/2*$C37*(E11+0.001)^2*$A$4)*($B$4+$C$4*E24^2),(1/2*$C37*(E11+0.001)^2*$A$4)*($B$4+$C$6*E24^2)) -> 4.1686727e+09 | F37: =IF(F$27<=0.7,(1/2*$C37*(F11+0.001)^2*$A$4)*($B$4+$C$4*F24^2),(1/2*$C37*(F11+0.001)^2*$A$4)*($B$4+$C$6*F24^2)) -> 420386.19 | G37: =IF(G$27<=0.7,(1/2*$C37*(G11+0.001)^2*$A$4)*($B$4+$C$4*G24^2),(1/2*$C37*(G11+0.001)^2*$A$4)*($B$4+$C$6*G24^2)) -> 108233.77 | H37: =IF(H$27<=0.7,(1/2*$C37*(H11+0.001)^2*$A$4)*($B$4+$C$4*H24^2),(1/2*$C37*(H11+0.001)^2*$A$4)*($B$4+$C$6*H24^2)) -> 54139.837 | I37: =IF(I$27<=0.7,(1/2*$C37*(I11+0.001)^2*$A$4)*($B$4+$C$4*I24^2),(1/2*$C37*(I11+0.001)^2*$A$4)*($B$4+$C$6*I24^2)) -> 39593.954 | J37: =IF(J$27<=0.7,(1/2*$C37*(J11+0.001)^2*$A$4)*($B$4+$C$4*J24^2),(1/2*$C37*(J11+0.001)^2*$A$4)*($B$4+$C$6*J24^2)) -> 37674.655 | K37: =IF(K$27<=0.7,(1/2*$C37*(K11+0.001)^2*$A$4)*($B$4+$C$4*K24^2),(1/2*$C37*(K11+0.001)^2*$A$4)*($B$4+$C$6*K24^2)) -> 41738.886 | L37: =IF(L$27<=0.7,(1/2*$C37*(L11+0.001)^2*$A$4)*($B$4+$C$4*L24^2),(1/2*$C37*(L11+0.001)^2*$A$4)*($B$4+$C$6*L24^2)) -> 49510.437 | ... O37: =IF(O$27<=0.7,(1/2*$C37*(O11+0.001)^2*$A$4)*($B$4+$C$4*O24^2),(1/2*$C37*(O11+0.001)^2*$A$4)*($B$4+$C$6*O24^2)) -> 91547.243
C38: 0.4671 | D38: 9000 | E38: =IF(E$27<=0.7,(1/2*$C38*(E12+0.001)^2*$A$4)*($B$4+$C$4*E25^2),(1/2*$C38*(E12+0.001)^2*$A$4)*($B$4+$C$6*E25^2)) -> 4.8258808e+09 | F38: =IF(F$27<=0.7,(1/2*$C38*(F12+0.001)^2*$A$4)*($B$4+$C$4*F25^2),(1/2*$C38*(F12+0.001)^2*$A$4)*($B$4+$C$6*F25^2)) -> 486460.18 | G38: =IF(G$27<=0.7,(1/2*$C38*(G12+0.001)^2*$A$4)*($B$4+$C$4*G25^2),(1/2*$C38*(G12+0.001)^2*$A$4)*($B$4+$C$6*G25^2)) -> 124325.84 | H38: =IF(H$27<=0.7,(1/2*$C38*(H12+0.001)^2*$A$4)*($B$4+$C$4*H25^2),(1/2*$C38*(H12+0.001)^2*$A$4)*($B$4+$C$6*H25^2)) -> 60469.549 | I38: =IF(I$27<=0.7,(1/2*$C38*(I12+0.001)^2*$A$4)*($B$4+$C$4*I25^2),(1/2*$C38*(I12+0.001)^2*$A$4)*($B$4+$C$6*I25^2)) -> 41908.977 | J38: =IF(J$27<=0.7,(1/2*$C38*(J12+0.001)^2*$A$4)*($B$4+$C$4*J25^2),(1/2*$C38*(J12+0.001)^2*$A$4)*($B$4+$C$6*J25^2)) -> 37475.546 | K38: =IF(K$27<=0.7,(1/2*$C38*(K12+0.001)^2*$A$4)*($B$4+$C$4*K25^2),(1/2*$C38*(K12+0.001)^2*$A$4)*($B$4+$C$6*K25^2)) -> 39478.2 | L38: =IF(L$27<=0.7,(1/2*$C38*(L12+0.001)^2*$A$4)*($B$4+$C$4*L25^2),(1/2*$C38*(L12+0.001)^2*$A$4)*($B$4+$C$6*L25^2)) -> 45281.633 | ... O38: =IF(O$27<=0.7,(1/2*$C38*(O12+0.001)^2*$A$4)*($B$4+$C$4*O25^2),(1/2*$C38*(O12+0.001)^2*$A$4)*($B$4+$C$6*O25^2)) -> 81419.249
C39: 0.4135 | D39: 10000 | E39: =IF(E$27<=0.7,(1/2*$C39*(E13+0.001)^2*$A$4)*($B$4+$C$4*E26^2),(1/2*$C39*(E13+0.001)^2*$A$4)*($B$4+$C$6*E26^2)) -> 5.6085671e+09 | F39: =IF(F$27<=0.7,(1/2*$C39*(F13+0.001)^2*$A$4)*($B$4+$C$4*F26^2),(1/2*$C39*(F13+0.001)^2*$A$4)*($B$4+$C$6*F26^2)) -> 565191.59 | G39: =IF(G$27<=0.7,(1/2*$C39*(G13+0.001)^2*$A$4)*($B$4+$C$4*G26^2),(1/2*$C39*(G13+0.001)^2*$A$4)*($B$4+$C$6*G26^2)) -> 143631.45 | H39: =IF(H$27<=0.7,(1/2*$C39*(H13+0.001)^2*$A$4)*($B$4+$C$4*H26^2),(1/2*$C39*(H13+0.001)^2*$A$4)*($B$4+$C$6*H26^2)) -> 68322.017 | I39: =IF(I$27<=0.7,(1/2*$C39*(I13+0.001)^2*$A$4)*($B$4+$C$4*I26^2),(1/2*$C39*(I13+0.001)^2*$A$4)*($B$4+$C$6*I26^2)) -> 45223.662 | J39: =IF(J$27<=0.7,(1/2*$C39*(J13+0.001)^2*$A$4)*($B$4+$C$4*J26^2),(1/2*$C39*(J13+0.001)^2*$A$4)*($B$4+$C$6*J26^2)) -> 38109.345 | K39: =IF(K$27<=0.7,(1/2*$C39*(K13+0.001)^2*$A$4)*($B$4+$C$4*K26^2),(1/2*$C39*(K13+0.001)^2*$A$4)*($B$4+$C$6*K26^2)) -> 38039.794 | L39: =IF(L$27<=0.7,(1/2*$C39*(L13+0.001)^2*$A$4)*($B$4+$C$4*L26^2),(1/2*$C39*(L13+0.001)^2*$A$4)*($B$4+$C$6*L26^2)) -> 41952.012 | ... O39: =IF(O$27<=0.7,(1/2*$C39*(O13+0.001)^2*$A$4)*($B$4+$C$4*O26^2),(1/2*$C39*(O13+0.001)^2*$A$4)*($B$4+$C$6*O26^2)) -> 72840.183
C42: TR | D42: Mach
...
